Workbook

Sheet Planilha1
B1: 45962 | C1: 45992 | D1: 46023 | E1: 46054 | F1: 46082 | G1: 46113 | H1: 46143 | I1: 46174 | J1: 46204 | K1: 46235 | L1: 46266 | M1: 46296 | N1: 46327 | O1: 46357
A2: Fluxo de caixa
A3: Total Saldo acumulado | C3: =C30-C7 -> 3202.09 | D3: =D30-D7 -> 3625.38 | E3: =E30-E7 -> 678.15 | F3: =F30-F7 -> -2265.83 | G3: =G30-G7 -> -4367.9 | H3: =H30-H7 -> -6408.45 | I3: =I30-I7 -> -8449 | J3: =J30-J7 -> -10181.78 | ... O3: =O30-O7 -> -18543.89
A4: Total Saldo operacional | C4: =C31-C8 -> 3358.65 | D4: =D31-D8 -> 423.29 | E4: =E31-E8 -> -2947.23 | F4: =F31-F8 -> -2943.98 | G4: =G31-G8 -> -2102.07 | H4: =H31-H8 -> -2040.55 | I4: =I31-I8 -> -2040.55 | J4: =J31-J8 -> -1732.78 | ... O4: =O31-O8 -> -1565.78
A6: Dívidas
A7: Saldo acumulado | C7: =B8+C8 -> 1269.68 | D7: =C7+D8 -> 4108.98 | E7: =D7+E8 -> 7056.21 | F7: =E7+F8 -> 10000.19 | G7: =F7+G8 -> 12102.26 | H7: =G7+H8 -> 14142.81 | I7: =H7+I8 -> 16183.36 | J7: =I7+J8 -> 17916.14 | K7: =J7+K8 -> 19648.92 | ... O7: =N7+O8 -> 26278.25
A8: Saldo Opercional | B8: =SUM(B9,B17,B14,B18,B21,B27) -> 156.56 | C8: =SUM(C9,C17,C14,C18,C21,C27) -> 1113.12 | D8: =SUM(D9,D17,D14,D18,D21,D27) -> 2839.3 | E8: =SUM(E9,E17,E14,E18,E21,E27) -> 2947.23 | F8: =SUM(F9,F17,F14,F18,F21,F27) -> 2943.98 | G8: =SUM(G9,G17,G14,G18,G21,G27) -> 2102.07 | H8: =SUM(H9,H17,H14,H18,H21,H27) -> 2040.55 | I8: =SUM(I9,I17,I14,I18,I21,I27) -> 2040.55 | ... O8: =SUM(O9,O17,O14,O18,O21,O27) -> 1565.78
A9: 1. Fat. Cartão | B9: =SUM(B10,B11,B12,B13) -> 0 | C9: =SUM(C10,C11,C12,C13) -> 0 | D9: =SUM(D10,D11,D12,D13) -> 1221.52 | E9: =SUM(E10,E11,E12,E13) -> 926.04 | F9: =SUM(F10,F11,F12,F13) -> 922.79 | G9: =SUM(G10,G11,G12,G13) -> 527.16 | H9: =SUM(H10,H11,H12,H13) -> 465.64 | I9: =SUM(I10,I11,I12,I13) -> 465.64 | ... O9: =SUM(O10,O11,O12,O13) -> 195.81
A10: 1.2 Santander | E10: =SUMIF(Planilha2!$E:$E,"Santander.2",Planilha2!$D:$D) -> 0 | F10: =SUMIF(Planilha2!$E:$E,"Santander.3",Planilha2!$D:$D) -> 0 | G10: =SUMIF(Planilha2!$E:$E,"Santander.4",Planilha2!$D:$D) -> 0 | H10: =SUMIF(Planilha2!$E:$E,"Santander.5",Planilha2!$D:$D) -> 0 | I10: =SUMIF(Planilha2!$E:$E,"Santander.6",Planilha2!$D:$D) -> 0 | J10: =SUMIF(Planilha2!$E:$E,"Santander.7",Planilha2!$D:$D) -> 0 | K10: =SUMIF(Planilha2!$E:$E,"Santander.8",Planilha2!$D:$D) -> 0 | L10: =SUMIF(Planilha2!$E:$E,"Santander.9",Planilha2!$D:$D) -> 0 | M10: =SUMIF(Planilha2!$E:$E,"Santander.10",Planilha2!$D:$D) -> 0 | N10: =SUMIF(Planilha2!$E:$E,"Santander.11",Planilha2!$D:$D) -> 0 | O10: =SUMIF(Planilha2!$E:$E,"Santander.12",Planilha2!$D:$D) -> 0
A11: 1.3 Itaú | D11: 490 | E11: 623.38 | F11: =SUMIF(Planilha2!$E:$E,"Crt. Itaú.3",Planilha2!$D:$D) -> 620.13 | G11: =SUMIF(Planilha2!$E:$E,"Crt. Itaú.4",Planilha2!$D:$D) -> 224.5 | H11: =SUMIF(Planilha2!$E:$E,"Crt. Itaú.5",Planilha2!$D:$D) -> 162.98 | I11: =SUMIF(Planilha2!$E:$E,"Crt. Itaú.6",Planilha2!$D:$D) -> 162.98 | J11: =SUMIF(Planilha2!$E:$E,"Crt. Itaú.7",Planilha2!$D:$D) -> 147.87 | K11: =SUMIF(Planilha2!$E:$E,"Crt. Itaú.8",Planilha2!$D:$D) -> 147.87 | L11: =SUMIF(Planilha2!$E:$E,"Crt. Itaú.9",Planilha2!$D:$D) -> 102.94 | M11: =SUMIF(Planilha2!$E:$E,"Crt. Itaú.10",Planilha2!$D:$D) -> 102.94 | N11: =SUMIF(Planilha2!$E:$E,"Crt. Itaú.11",Planilha2!$D:$D) -> 102.94 | O11: =SUMIF(Planilha2!$E:$E,"Crt. Itaú.12",Planilha2!$D:$D) -> 0
A12: 1.4 MP CA | D12: 127.82 | E12: =SUMIF(Planilha2!$E:$E,"Crt. MP CA.2",Planilha2!$D:$D) -> 283.53 | F12: =SUMIF(Planilha2!$E:$E,"Crt. MP CA.3",Planilha2!$D:$D) -> 283.53 | G12: =SUMIF(Planilha2!$E:$E,"Crt. MP CA.4",Planilha2!$D:$D) -> 283.53 | H12: =SUMIF(Planilha2!$E:$E,"Crt. MP CA.5",Planilha2!$D:$D) -> 283.53 | I12: =SUMIF(Planilha2!$E:$E,"Crt. MP CA.6",Planilha2!$D:$D) -> 283.53 | J12: =SUMIF(Planilha2!$E:$E,"Crt. MP CA.7",Planilha2!$D:$D) -> 195.81 | K12: =SUMIF(Planilha2!$E:$E,"Crt. MP CA.8",Planilha2!$D:$D) -> 195.81 | L12: =SUMIF(Planilha2!$E:$E,"Crt. MP CA.9",Planilha2!$D:$D) -> 195.81 | M12: =SUMIF(Planilha2!$E:$E,"Crt. MP CA.10",Planilha2!$D:$D) -> 195.81 | N12: =SUMIF(Planilha2!$E:$E,"Crt. MP CA.11",Planilha2!$D:$D) -> 195.81 | O12: =SUMIF(Planilha2!$E:$E,"Crt. MP CA.12",Planilha2!$D:$D) -> 195.81
A13: 1.5 MP MA | D13: 603.7 | E13: =SUMIF(Planilha2!$E:$E,"Crt. MP MA.2",Planilha2!$D:$D) -> 19.13 | F13: =SUMIF(Planilha2!$E:$E,"Crt. MP MA.3",Planilha2!$D:$D) -> 19.13 | G13: =SUMIF(Planilha2!$E:$E,"Crt. MP MA.4",Planilha2!$D:$D) -> 19.13 | H13: =SUMIF(Planilha2!$E:$E,"Crt. MP MA.5",Planilha2!$D:$D) -> 19.13 | I13: =SUMIF(Planilha2!$E:$E,"Crt. MP MA.6",Planilha2!$D:$D) -> 19.13 | J13: =SUMIF(Planilha2!$E:$E,"Crt. MP MA.7",Planilha2!$D:$D) -> 19.13 | K13: =SUMIF(Planilha2!$E:$E,"Crt. MP MA.8",Planilha2!$D:$D) -> 19.13 | L13: =SUMIF(Planilha2!$E:$E,"Crt. MP MA.9",Planilha2!$D:$D) -> 19.13 | M13: =SUMIF(Planilha2!$E:$E,"Crt. MP MA.10",Planilha2!$D:$D) -> 19.13 | N13: =SUMIF(Planilha2!$E:$E,"Crt. MP MA.11",Planilha2!$D:$D) -> 19.13 | O13: =SUMIF(Planilha2!$E:$E,"Crt. MP MA.12",Planilha2!$D:$D) -> 0
A14: 3 Empréstimos | D14: =SUM(D15,D16,D17) -> 660.12 | E14: =SUM(E15,E16,E17) -> 883.26 | F14: =SUM(F15,F16,F17) -> 883.26 | G14: =SUM(G15,G16,G17) -> 660.12 | H14: =SUM(H15,H16,H17) -> 660.12 | I14: =SUM(I15,I16,I17) -> 660.12 | J14: =SUM(J15,J16,J17) -> 660.12 | K14: =SUM(K15,K16,K17) -> 660.12 | ... O14: =SUM(O15,O16,O17) -> 660.12
A15: 3.1 Carro | D15: 404.89 | E15: 404.89 | F15: 404.89 | G15: 404.89 | H15: 404.89 | I15: 404.89 | J15: 404.89 | K15: 404.89 | L15: 404.89 | M15: 404.89 | N15: 404.89 | O15: 404.89
A16: 3.2 Contas | D16: 255.23 | E16: 255.23 | F16: 255.23 | G16: 255.23 | H16: 255.23 | I16: 255.23 | J16: 255.23 | K16: 255.23 | L16: 255.23 | M16: 255.23 | N16: 255.23 | O16: 255.23
A17: 3.3 Pic pay | D17: 0 | E17: 223.14 | F17: 223.14
A18: 4 Habitação | C18: =SUM(C19,C20) -> 0 | D18: =SUM(D19,D20) -> 515.45 | E18: =SUM(E19,E20) -> 505.8 | F18: =SUM(F19,F20) -> 505.8 | G18: =SUM(G19,G20) -> 505.8 | H18: =SUM(H19,H20) -> 505.8 | I18: =SUM(I19,I20) -> 505.8 | J18: =SUM(J19,J20) -> 300.86 | ... O18: =SUM(O19,O20) -> 300.86
A19: Finan. Casa | D19: 310.51 | E19: 300.86 | F19: 300.86 | G19: 300.86 | H19: 300.86 | I19: 300.86 | J19: 300.86 | K19: 300.86 | L19: 300.86 | M19: 300.86 | N19: 300.86 | O19: 300.86
A20: IPTU | D20: 204.94 | E20: 204.94 | F20: 204.94 | G20: 204.94 | H20: 204.94 | I20: 204.94
A21: 5 Despesas | B21: =SUM(B22,B23,B24,B25) -> 156.56 | C21: =SUM(C22,C23,C24,C25,C26) -> 1113.12 | D21: =SUM(D22,D23,D24,D25,D26) -> 442.21 | E21: =SUM(E22,E23,E24,E25,E26) -> 408.99 | F21: =SUM(F22,F23,F24,F25,F26) -> 408.99 | G21: =SUM(G22,G23,G24,G25,G26) -> 408.99 | H21: =SUM(H22,H23,H24,H25,H26) -> 408.99 | I21: =SUM(I22,I23,I24,I25,I26) -> 408.99 | J21: =SUM(J22,J23,J24,J25,J26) -> 408.99 | ... O21: =SUM(O22,O23,O24,O25,O26) -> 408.99
A22: 5.1 Água | B22: 156.56 | C22: 133.09 | D22: 133.09 | E22: 133.09 | F22: 133.09 | G22: 133.09 | H22: 133.09 | I22: 133.09 | J22: 133.09 | K22: 133.09 | L22: 133.09 | M22: 133.09 | N22: 133.09 | O22: 133.09
A23: 5.2 Energia | C23: =237.75+196.38 -> 434.13 | D23: 213.22 | E23: 180 | F23: 180 | G23: 180 | H23: 180 | I23: 180 | J23: 180 | K23: 180 | L23: 180 | M23: 180 | N23: 180 | O23: 180
A24: 5.3 Internet | C24: 75 | D24: 75 | E24: 75 | F24: 75 | G24: 75 | H24: 75 | I24: 75 | J24: 75 | K24: 75 | L24: 75 | M24: 75 | N24: 75 | O24: 75
A25: 5.4 Saúde | C25: 450
A26: 5.5 Netflix | C26: 20.9 | D26: 20.9 | E26: 20.9 | F26: 20.9 | G26: 20.9 | H26: 20.9 | I26: 20.9 | J26: 20.9 | K26: 20.9 | L26: 20.9 | M26: 20.9 | N26: 20.9 | O26: 20.9
A27: 6 Dízimo
A29: Receitas
A30: Saldo acumulado | C30: =C31 -> 4471.77 | D30: =C30+D31 -> 7734.36 | E30: =D30+E31 -> 7734.36 | F30: =E30+F31 -> 7734.36 | G30: =F30+G31 -> 7734.36 | H30: =G30+H31 -> 7734.36 | I30: =H30+I31 -> 7734.36 | J30: =I30+J31 -> 7734.36 | K30: =J30+K31 -> 7734.36 | ... O30: =N30+O31 -> 7734.36
A31: Saldo operacional | C31: =SUM(C32,C37,C38) -> 4471.77 | D31: =SUM(D32,D37,D38) -> 3262.59 | E31: =SUM(E32,E37,E38) -> 0 | F31: =SUM(F32,F37,F38) -> 0 | G31: =SUM(G32,G37,G38) -> 0 | H31: =SUM(H32,H37,H38) -> 0 | I31: =SUM(I32,I37,I38) -> 0 | J31: =SUM(J32,J37,J38) -> 0 | ... O31: =SUM(O32,O37,O38) -> 0
A32: 1 Ganhos STMIL | B32: =SUM(B34,B35) -> 0 | C32: =SUM(C33,C34,C35,C36) -> 4287.45 | D32: =SUM(D33,D34,D35,D36) -> 2988.59 | E32: =SUM(E33,E34,E35,E36) -> 0 | F32: =SUM(F33,F34,F35,F36) -> 0 | G32: =SUM(G33,G34,G35,G36) -> 0 | H32: =SUM(H33,H34,H35,H36) -> 0 | I32: =SUM(I33,I34,I35,I36) -> 0 | J32: =SUM(J33,J34,J35,J36) -> 0 | ... O32: =SUM(O33,O34,O35,O36) -> 0
A33: 1.1 Salário | C33: 2588.59 | D33: 2588.59
A34: 1.2 13° | C34: 1298.86
A35: 1.3 Férias
A36: 1.4 Alelo (Alimentação) | C36: 400 | D36: 400
A37: 2 Outras Fontes | D37: 80
A38: 3 Empréstimos | C38: 184.32 | D38: 194

Sheet Planilha2
A1: Despesas
A2: DATA COMPRA | B2: DOC. | C2: FORNECEDOR | D2: VALOR
A3: 45634 | C3: Mercado Livre Ebazar (14/18) | D3: 53.55 | E3: Crt. MP CA.2
A4: 45634 | C4: Mercado Livre Ebazar (15/18) | D4: 53.55 | E4: Crt. MP CA.3
A5: 45634 | C5: Mercado Livre Ebazar (16/18) | D5: 53.55 | E5: Crt. MP CA.4
A6: 45634 | C6: Mercado Livre Ebazar (17/18) | D6: 53.55 | E6: Crt. MP CA.5
A7: 45634 | C7: Mercado Livre Ebazar (18/18) | D7: 53.55 | E7: Crt. MP CA.6
A8: 45801 | C8: Mercado Livre (9/13) | D8: 34.17 | E8: Crt. MP CA.2
A9: 45801 | C9: Mercado Livre (10/13) | D9: 34.17 | E9: Crt. MP CA.3
A10: 45801 | C10: Mercado Livre (11/13) | D10: 34.17 | E10: Crt. MP CA.4
A11: 45801 | C11: Mercado Livre (12/13) | D11: 34.17 | E11: Crt. MP CA.5
A12: 45801 | C12: Mercado Livre (13/13) | D12: 34.17 | E12: Crt. MP CA.6
A13: 45832 | C13: Mercado Livre 8/12 | D13: 15.11 | E13: Crt. Itaú.2
A14: 45832 | C14: Mercado Livre 9/12 | D14: 15.11 | E14: Crt. Itaú.3
... A65: 46022 | C65: Loja Vitória | D65: 32 | E65: Crt. Itaú.2
A66: 46022 | D66: 30 | E66: Crt. Itaú.2
A67: 46023 | B67: 105326 | C67: Allegra | D67: 39.36 | E67: Crt. Itaú.2
A68: 46024 | B68: 70335 | C68: Sup. Brasil | D68: 42.17 | E68: Crt. Itaú.2
A69: 46024 | C69: Magazine Calvest | D69: 22.94 | E69: Crt. Itaú.2
A70: 46024 | C70: Magazine Calvest | D70: 22.94 | E70: Crt. Itaú.3
A71: 46024 | C71: Magazine Calvest | D71: 22.94 | E71: Crt. Itaú.4
A72: 46024 | C72: Magazine Calvest | D72: 22.94 | E72: Crt. Itaú.5
A73: 46024 | C73: Magazine Calvest | D73: 22.94 | E73: Crt. Itaú.6
A74: 46024 | C74: Magazine Calvest | D74: 22.94 | E74: Crt. Itaú.7
A75: 46024 | C75: Magazine Calvest | D75: 22.94 | E75: Crt. Itaú.8
A76: 46024 | C76: Magazine Calvest | D76: 22.94 | E76: Crt. Itaú.9
A77: 46024 | C77: Magazine Calvest | D77: 22.94 | E77: Crt. Itaú.10
A78: 46024 | C78: Magazine Calvest | D78: 22.94 | E78: Crt. Itaú.11
A79: 46025 | B79: 95295 | C79: Americanas | D79: 9.99 | E79: Crt. Itaú.2
A80: 46025 | B80: 484579 | C80: Ultramed | D80: 20 | E80: Crt. Itaú.2
A81: 46025 | C81: Sup. Brasil | D81: 58.01 | E81: Crt. Itaú.2
A82: 46025 | C82: Posto Globo | D82: 40 | E82: Crt. Itaú.2
A83: 46026 | B83: 106034 | C83: Allegra | D83: 62.54 | E83: Crt. Itaú.2
A84: 46026 | B84: 613183 | C84: Smart | D84: 30.67 | E84: Crt. Itaú.2
A85: 46027 | C85: Posto Globo | D85: 30 | E85: Crt. Itaú.2
A86: 46028 | C86: Mercado Prime | D86: 26.5 | E86: Crt. Itaú.2
A87: 46029 | B87: 113959 | C87: Allegra | D87: 42.25 | E87: Crt. Itaú.2
A88: 46029 | B88: 336035 | C88: Sup. Bom Preço | D88: 9.56 | E88: Crt. Itaú.2
A89: 46031 | C89: Posto WK | D89: 30 | E89: Crt. Itaú.2
A90: 46031 | B90: 118315 | C90: Americanas | D90: 9.99 | E90: Crt. Itaú.2
...
